2023-07-01 11:33:05.826052: I tensorflow/core/platform/cpu_feature_guard.cc:193] This TensorFlow binary is optimized with oneAPI Deep Neural Network Library (oneDNN) to use the following CPU instructions in performance-critical operations:  AVX AVX2
To enable them in other operations, rebuild TensorFlow with the appropriate compiler flags.

1/4 [======>.......................] - ETA: 1s - loss: 1.2588
4/4 [==============================] - 0s 5ms/step - loss: 1.2581
Epoch 1/10
Traceback (most recent call last):
  File "C:\Users\XYZ\Downloads\Bug Reproducibility\Bugs\018\main.py", line 21, in <module>
    model.fit(train_X, train_Y, epochs=10)
  File "C:\Users\XYZ\Downloads\Bug Reproducibility\venv\lib\site-packages\keras\utils\traceback_utils.py", line 70, in error_handler
    raise e.with_traceback(filtered_tb) from None
  File "C:\Users\XYZ\Downloads\Bug Reproducibility\venv\lib\site-packages\tensorflow\python\eager\execute.py", line 52, in quick_execute
    tensors = pywrap_tfe.TFE_Py_Execute(ctx._handle, device_name, op_name,
tensorflow.python.framework.errors_impl.InvalidArgumentError: Graph execution error:

Detected at node 'gradient_tape/custom_loss_1/mul/BroadcastGradientArgs' defined at (most recent call last):
    File "C:\Users\XYZ\Downloads\Bug Reproducibility\Bugs\018\main.py", line 21, in <module>
      model.fit(train_X, train_Y, epochs=10)
    File "C:\Users\XYZ\Downloads\Bug Reproducibility\venv\lib\site-packages\keras\utils\traceback_utils.py", line 65, in error_handler
      return fn(*args, **kwargs)
    File "C:\Users\XYZ\Downloads\Bug Reproducibility\venv\lib\site-packages\keras\engine\training.py", line 1650, in fit
      tmp_logs = self.train_function(iterator)
    File "C:\Users\XYZ\Downloads\Bug Reproducibility\venv\lib\site-packages\keras\engine\training.py", line 1249, in train_function
      return step_function(self, iterator)
    File "C:\Users\XYZ\Downloads\Bug Reproducibility\venv\lib\site-packages\keras\engine\training.py", line 1233, in step_function
      outputs = model.distribute_strategy.run(run_step, args=(data,))
    File "C:\Users\XYZ\Downloads\Bug Reproducibility\venv\lib\site-packages\keras\engine\training.py", line 1222, in run_step
      outputs = model.train_step(data)
    File "C:\Users\XYZ\Downloads\Bug Reproducibility\venv\lib\site-packages\keras\engine\training.py", line 1027, in train_step
      self.optimizer.minimize(loss, self.trainable_variables, tape=tape)
    File "C:\Users\XYZ\Downloads\Bug Reproducibility\venv\lib\site-packages\keras\optimizers\optimizer_experimental\optimizer.py", line 526, in minimize
      grads_and_vars = self.compute_gradients(loss, var_list, tape)
    File "C:\Users\XYZ\Downloads\Bug Reproducibility\venv\lib\site-packages\keras\optimizers\optimizer_experimental\optimizer.py", line 259, in compute_gradients
      grads = tape.gradient(loss, var_list)
Node: 'gradient_tape/custom_loss_1/mul/BroadcastGradientArgs'
Incompatible shapes: [32,5] vs. [100,5]
	 [[{{node gradient_tape/custom_loss_1/mul/BroadcastGradientArgs}}]] [Op:__inference_train_function_1016]
