2023-07-13 11:58:02.305126: I tensorflow/core/platform/cpu_feature_guard.cc:182] This TensorFlow binary is optimized to use available CPU instructions in performance-critical operations.
To enable the following instructions: SSE SSE2 SSE3 SSE4.1 SSE4.2 AVX AVX2 AVX512F AVX512_VNNI FMA, in other operations, rebuild TensorFlow with the appropriate compiler flags.
(70, 7) (15, 7) (15, 7) (70,) (15,) (15,)
Traceback (most recent call last):
  File "C:\Users\Mehil Shah\Downloads\Research Projects\Bug Reproducibility\Bugs\064\main.py", line 42, in <module>
    model.evaluate(X_test, Y_test)[1] ##Type Error is here!
  File "C:\Users\Mehil Shah\Downloads\Research Projects\Bug Reproducibility\venv\lib\site-packages\keras\src\utils\traceback_utils.py", line 70, in error_handler
    raise e.with_traceback(filtered_tb) from None
  File "C:\Users\MEHILS~1\AppData\Local\Temp\__autograph_generated_file3_sv5zet.py", line 15, in tf__test_function
    retval_ = ag__.converted_call(ag__.ld(step_function), (ag__.ld(self), ag__.ld(iterator)), None, fscope)
TypeError: in user code:

    File "C:\Users\Mehil Shah\Downloads\Research Projects\Bug Reproducibility\venv\lib\site-packages\keras\src\engine\training.py", line 1972, in test_function  *
        return step_function(self, iterator)
    File "C:\Users\Mehil Shah\Downloads\Research Projects\Bug Reproducibility\venv\lib\site-packages\keras\src\engine\training.py", line 1956, in step_function  **
        outputs = model.distribute_strategy.run(run_step, args=(data,))
    File "C:\Users\Mehil Shah\Downloads\Research Projects\Bug Reproducibility\venv\lib\site-packages\keras\src\engine\training.py", line 1944, in run_step  **
        outputs = model.test_step(data)
    File "C:\Users\Mehil Shah\Downloads\Research Projects\Bug Reproducibility\venv\lib\site-packages\keras\src\engine\training.py", line 1850, in test_step
        y_pred = self(x, training=False)
    File "C:\Users\Mehil Shah\Downloads\Research Projects\Bug Reproducibility\venv\lib\site-packages\keras\src\utils\traceback_utils.py", line 70, in error_handler
        raise e.with_traceback(filtered_tb) from None
    File "C:\Users\Mehil Shah\Downloads\Research Projects\Bug Reproducibility\venv\lib\site-packages\keras\src\engine\base_layer.py", line 2810, in _name_scope
        name_scope += "/"

    TypeError: unsupported operand type(s) for +=: 'Dense' and 'str'

