2023-07-25 10:59:27.386412: I tensorflow/core/platform/cpu_feature_guard.cc:193] This TensorFlow binary is optimized with oneAPI Deep Neural Network Library (oneDNN) to use the following CPU instructions in performance-critical operations:  AVX AVX2
To enable them in other operations, rebuild TensorFlow with the appropriate compiler flags.
C:\Users\Mehil Shah\AppData\Local\Programs\Python\Python310\lib\site-packages\keras\optimizers\optimizer_v2\gradient_descent.py:114: UserWarning: The `lr` argument is deprecated, use `learning_rate` instead.
  super().__init__(name, **kwargs)
Traceback (most recent call last):
  File "C:\Users\Mehil Shah\Downloads\Research Projects\Bug Reproducibility\Bugs\096\original_code_snippet.py", line 50, in <module>
    history = vgg19.fit(X, Y, epochs=100, batch_size=64, validation_data=(tsX, tsY), verbose=0)
  File "C:\Users\Mehil Shah\AppData\Local\Programs\Python\Python310\lib\site-packages\keras\utils\traceback_utils.py", line 70, in error_handler
    raise e.with_traceback(filtered_tb) from None
  File "C:\Users\MEHILS~1\AppData\Local\Temp\__autograph_generated_filehga7igau.py", line 15, in tf__train_function
    retval_ = ag__.converted_call(ag__.ld(step_function), (ag__.ld(self), ag__.ld(iterator)), None, fscope)
ValueError: in user code:

    File "C:\Users\Mehil Shah\AppData\Local\Programs\Python\Python310\lib\site-packages\keras\engine\training.py", line 1249, in train_function  *
        return step_function(self, iterator)
    File "C:\Users\Mehil Shah\AppData\Local\Programs\Python\Python310\lib\site-packages\keras\engine\training.py", line 1233, in step_function  **
        outputs = model.distribute_strategy.run(run_step, args=(data,))
    File "C:\Users\Mehil Shah\AppData\Local\Programs\Python\Python310\lib\site-packages\keras\engine\training.py", line 1222, in run_step  **
        outputs = model.train_step(data)
    File "C:\Users\Mehil Shah\AppData\Local\Programs\Python\Python310\lib\site-packages\keras\engine\training.py", line 1023, in train_step
        y_pred = self(x, training=True)
    File "C:\Users\Mehil Shah\AppData\Local\Programs\Python\Python310\lib\site-packages\keras\utils\traceback_utils.py", line 70, in error_handler
        raise e.with_traceback(filtered_tb) from None
    File "C:\Users\Mehil Shah\AppData\Local\Programs\Python\Python310\lib\site-packages\keras\engine\input_spec.py", line 295, in assert_input_compatibility
        raise ValueError(

    ValueError: Input 0 of layer "sequential" is incompatible with the layer: expected shape=(None, 224, 224, 3), found shape=(None, 32, 32, 3)

